<?xml version="1.0"?>
<robot xmlns:xacro="http://ros.org/wiki/xacro">

<xacro:arg name="mesh_url" default="package://helix_description" />

<!-- Import Rviz colors -->
<xacro:include filename="$(find helix_description)/urdf/dynamixel_block.material.xacro" />


<xacro:macro name="dynamixel_block" params="parent *origin">

  <joint name="origin_to_dynamixel_block" type="fixed">
    <xacro:insert_block name="origin" />
    <parent link="${parent}" />
    <child link="dynamixel_block" />
    <!-- <axis xyz="0 0 0" /> -->
  </joint>


  <link name="dynamixel_block">
    <inertial>
      <origin xyz="2.0953375978834464e-10 -1.1130157562643936e-15 0.04950000000000035" rpy="0 0 0"/>
      <mass value="4.068765147265586"/>
      <inertia ixx="0.00523" iyy="0.005791" izz="0.004781" ixy="-0.0" iyz="0.0" ixz="-0.0"/>
    </inertial>
    <visual>
      <origin xyz="0 0 0" rpy="0 0 0"/>
      <geometry>
        <mesh filename="$(arg mesh_url)/meshes/base_link.stl" scale="0.001 0.001 0.001"/>
      </geometry>
      <material name="dynamixel_body"/>
    </visual>
    <collision>
      <origin xyz="0 0 0" rpy="0 0 0"/>
      <geometry>
        <mesh filename="$(arg mesh_url)/meshes/base_link.stl" scale="0.001 0.001 0.001"/>
      </geometry>
    </collision>
  </link>


  <link name="horn_0_1">
    <inertial>
      <origin xyz="2.1600756947015576e-10 0.0012867771027071859 1.489363054274495e-07" rpy="0 0 0"/>
      <mass value="0.0051570798167471414"/>
      <inertia ixx="0.0" iyy="0.0" izz="0.0" ixy="0.0" iyz="-0.0" ixz="0.0"/>
    </inertial>
    <visual>
      <origin xyz="-0.03 -0.037 -0.08475" rpy="0 0 0"/>
      <geometry>
        <mesh filename="$(arg mesh_url)/meshes/horn_0_1.stl" scale="0.001 0.001 0.001"/>
      </geometry>
      <material name="dynamixel_horn"/>
    </visual>
    <collision>
      <origin xyz="-0.03 -0.037 -0.08475" rpy="0 0 0"/>
      <geometry>
        <mesh filename="$(arg mesh_url)/meshes/horn_0_1.stl" scale="0.001 0.001 0.001"/>
      </geometry>
    </collision>
  </link>



  <link name="horn_1_1">
    <inertial>
      <origin xyz="2.1600756947015576e-10 0.0012867771027084557 1.4893630551765513e-07" rpy="0 0 0"/>
      <mass value="0.0051570798167471414"/>
      <inertia ixx="0.0" iyy="0.0" izz="0.0" ixy="0.0" iyz="-0.0" ixz="0.0"/>
    </inertial>
    <visual>
      <origin xyz="-0.03 -0.037 -0.01425" rpy="0 0 0"/>
      <geometry>
        <mesh filename="$(arg mesh_url)/meshes/horn_1_1.stl" scale="0.001 0.001 0.001"/>
      </geometry>
      <material name="dynamixel_horn"/>
    </visual>
    <collision>
      <origin xyz="-0.03 -0.037 -0.01425" rpy="0 0 0"/>
      <geometry>
        <mesh filename="$(arg mesh_url)/meshes/horn_1_1.stl" scale="0.001 0.001 0.001"/>
      </geometry>
    </collision>
  </link>

  <link name="horn_2_1">
    <inertial>
      <origin xyz="2.1600747412975353e-10 0.0012867771027066446 1.4893630553847181e-07" rpy="0 0 0"/>
      <mass value="0.0051570798167471414"/>
      <inertia ixx="0.0" iyy="0.0" izz="0.0" ixy="0.0" iyz="-0.0" ixz="0.0"/>
    </inertial>
    <visual>
      <origin xyz="-0.0 -0.037 -0.08475" rpy="0 0 0"/>
      <geometry>
        <mesh filename="$(arg mesh_url)/meshes/horn_2_1.stl" scale="0.001 0.001 0.001"/>
      </geometry>
      <material name="dynamixel_horn"/>
    </visual>
    <collision>
      <origin xyz="-0.0 -0.037 -0.08475" rpy="0 0 0"/>
      <geometry>
        <mesh filename="$(arg mesh_url)/meshes/horn_2_1.stl" scale="0.001 0.001 0.001"/>
      </geometry>
    </collision>
  </link>

  <link name="horn_3_1">
    <inertial>
      <origin xyz="2.160074785706456e-10 0.0012867771027079145 1.4893630551765513e-07" rpy="0 0 0"/>
      <mass value="0.0051570798167471414"/>
      <inertia ixx="0.0" iyy="0.0" izz="0.0" ixy="0.0" iyz="-0.0" ixz="0.0"/>
    </inertial>
    <visual>
      <origin xyz="-0.0 -0.037 -0.01425" rpy="0 0 0"/>
      <geometry>
        <mesh filename="$(arg mesh_url)/meshes/horn_3_1.stl" scale="0.001 0.001 0.001"/>
      </geometry>
      <material name="dynamixel_horn"/>
    </visual>
    <collision>
      <origin xyz="-0.0 -0.037 -0.01425" rpy="0 0 0"/>
      <geometry>
        <mesh filename="$(arg mesh_url)/meshes/horn_3_1.stl" scale="0.001 0.001 0.001"/>
      </geometry>
    </collision>
  </link>

  <link name="horn_4_1">
    <inertial>
      <origin xyz="2.160074515089594e-10 0.0012867771027060895 1.4893630560786075e-07" rpy="0 0 0"/>
      <mass value="0.0051570798167471414"/>
      <inertia ixx="0.0" iyy="0.0" izz="0.0" ixy="0.0" iyz="-0.0" ixz="0.0"/>
    </inertial>
    <visual>
      <origin xyz="0.03 -0.037 -0.08475" rpy="0 0 0"/>
      <geometry>
        <mesh filename="$(arg mesh_url)/meshes/horn_4_1.stl" scale="0.001 0.001 0.001"/>
      </geometry>
      <material name="dynamixel_horn"/>
    </visual>
    <collision>
      <origin xyz="0.03 -0.037 -0.08475" rpy="0 0 0"/>
      <geometry>
        <mesh filename="$(arg mesh_url)/meshes/horn_4_1.stl" scale="0.001 0.001 0.001"/>
      </geometry>
    </collision>
  </link>

  <link name="horn_5_1">
    <inertial>
      <origin xyz="2.1600743416172463e-10 0.0012867771027073802 1.4893630539275504e-07" rpy="0 0 0"/>
      <mass value="0.0051570798167471414"/>
      <inertia ixx="0.0" iyy="0.0" izz="0.0" ixy="0.0" iyz="-0.0" ixz="0.0"/>
    </inertial>
    <visual>
      <origin xyz="0.03 -0.037 -0.01425" rpy="0 0 0"/>
      <geometry>
        <mesh filename="$(arg mesh_url)/meshes/horn_5_1.stl" scale="0.001 0.001 0.001"/>
      </geometry>
      <material name="dynamixel_horn"/>
    </visual>
    <collision>
      <origin xyz="0.03 -0.037 -0.01425" rpy="0 0 0"/>
      <geometry>
        <mesh filename="$(arg mesh_url)/meshes/horn_5_1.stl" scale="0.001 0.001 0.001"/>
      </geometry>
    </collision>
  </link>

  <link name="horn_6_1">
    <inertial>
      <origin xyz="2.1600888439055055e-10 -0.0012867771027105165 -1.4893630470580455e-07" rpy="0 0 0"/>
      <mass value="0.0051570798167471414"/>
      <inertia ixx="0.0" iyy="0.0" izz="0.0" ixy="-0.0" iyz="-0.0" ixz="-0.0"/>
    </inertial>
    <visual>
      <origin xyz="0.03 0.037 -0.08475" rpy="0 0 0"/>
      <geometry>
        <mesh filename="$(arg mesh_url)/meshes/horn_6_1.stl" scale="0.001 0.001 0.001"/>
      </geometry>
      <material name="dynamixel_horn"/>
    </visual>
    <collision>
      <origin xyz="0.03 0.037 -0.08475" rpy="0 0 0"/>
      <geometry>
        <mesh filename="$(arg mesh_url)/meshes/horn_6_1.stl" scale="0.001 0.001 0.001"/>
      </geometry>
    </collision>
  </link>

  <link name="horn_7_1">
    <inertial>
      <origin xyz="2.1600883234884627e-10 -0.001286777102709219 -1.4893630484631715e-07" rpy="0 0 0"/>
      <mass value="0.0051570798167471414"/>
      <inertia ixx="0.0" iyy="0.0" izz="0.0" ixy="-0.0" iyz="-0.0" ixz="-0.0"/>
    </inertial>
    <visual>
      <origin xyz="0.03 0.037 -0.01425" rpy="0 0 0"/>
      <geometry>
        <mesh filename="$(arg mesh_url)/meshes/horn_7_1.stl" scale="0.001 0.001 0.001"/>
      </geometry>
      <material name="dynamixel_horn"/>
    </visual>
    <collision>
      <origin xyz="0.03 0.037 -0.01425" rpy="0 0 0"/>
      <geometry>
        <mesh filename="$(arg mesh_url)/meshes/horn_7_1.stl" scale="0.001 0.001 0.001"/>
      </geometry>
    </collision>
  </link>

  <link name="horn_8_1">
    <inertial>
      <origin xyz="2.160089485059302e-10 -0.0012867771027099684 -1.4893630470580455e-07" rpy="0 0 0"/>
      <mass value="0.0051570798167471414"/>
      <inertia ixx="0.0" iyy="0.0" izz="0.0" ixy="-0.0" iyz="-0.0" ixz="-0.0"/>
    </inertial>
    <visual>
      <origin xyz="-0.0 0.037 -0.08475" rpy="0 0 0"/>
      <geometry>
        <mesh filename="$(arg mesh_url)/meshes/horn_8_1.stl" scale="0.001 0.001 0.001"/>
      </geometry>
      <material name="dynamixel_horn"/>
    </visual>
    <collision>
      <origin xyz="-0.0 0.037 -0.08475" rpy="0 0 0"/>
      <geometry>
        <mesh filename="$(arg mesh_url)/meshes/horn_8_1.stl" scale="0.001 0.001 0.001"/>
      </geometry>
    </collision>
  </link>

  <link name="horn_9_1">
    <inertial>
      <origin xyz="2.1600887745165664e-10 -0.0012867771027086916 -1.489363048289699e-07" rpy="0 0 0"/>
      <mass value="0.0051570798167471414"/>
      <inertia ixx="0.0" iyy="0.0" izz="0.0" ixy="-0.0" iyz="-0.0" ixz="-0.0"/>
    </inertial>
    <visual>
      <origin xyz="-0.0 0.037 -0.01425" rpy="0 0 0"/>
      <geometry>
        <mesh filename="$(arg mesh_url)/meshes/horn_9_1.stl" scale="0.001 0.001 0.001"/>
      </geometry>
      <material name="dynamixel_horn"/>
    </visual>
    <collision>
      <origin xyz="-0.0 0.037 -0.01425" rpy="0 0 0"/>
      <geometry>
        <mesh filename="$(arg mesh_url)/meshes/horn_9_1.stl" scale="0.001 0.001 0.001"/>
      </geometry>
    </collision>
  </link>

  <link name="horn_10_1">
    <inertial>
      <origin xyz="2.1600893643225483e-10 -0.001286777102709441 -1.4893630466417118e-07" rpy="0 0 0"/>
      <mass value="0.0051570798167471414"/>
      <inertia ixx="0.0" iyy="0.0" izz="0.0" ixy="-0.0" iyz="-0.0" ixz="-0.0"/>
    </inertial>
    <visual>
      <origin xyz="-0.03 0.037 -0.08475" rpy="0 0 0"/>
      <geometry>
        <mesh filename="$(arg mesh_url)/meshes/horn_10_1.stl" scale="0.001 0.001 0.001"/>
      </geometry>
      <material name="dynamixel_horn"/>
    </visual>
    <collision>
      <origin xyz="-0.03 0.037 -0.08475" rpy="0 0 0"/>
      <geometry>
        <mesh filename="$(arg mesh_url)/meshes/horn_10_1.stl" scale="0.001 0.001 0.001"/>
      </geometry>
    </collision>
  </link>

  <link name="horn_11_1">
    <inertial>
      <origin xyz="2.1600900235174691e-10 -0.0012867771027081157 -1.489363048289699e-07" rpy="0 0 0"/>
      <mass value="0.0051570798167471414"/>
      <inertia ixx="0.0" iyy="0.0" izz="0.0" ixy="-0.0" iyz="-0.0" ixz="-0.0"/>
    </inertial>
    <visual>
      <origin xyz="-0.03 0.037 -0.01425" rpy="0 0 0"/>
      <geometry>
        <mesh filename="$(arg mesh_url)/meshes/horn_11_1.stl" scale="0.001 0.001 0.001"/>
      </geometry>
      <material name="dynamixel_horn"/>
    </visual>
    <collision>
      <origin xyz="-0.03 0.037 -0.01425" rpy="0 0 0"/>
      <geometry>
        <mesh filename="$(arg mesh_url)/meshes/horn_11_1.stl" scale="0.001 0.001 0.001"/>
      </geometry>
    </collision>
  </link>


  <joint name="dynamixel0" type="continuous">
    <origin xyz="0.03 0.037 0.08475" rpy="0 0 0"/>
    <parent link="dynamixel_block"/>
    <child link="horn_0_1"/>
    <axis xyz="0.0 1.0 0.0"/>
  </joint>

  <joint name="dynamixel1" type="continuous">
    <origin xyz="0.03 0.037 0.01425" rpy="0 0 0"/>
    <parent link="dynamixel_block"/>
    <child link="horn_1_1"/>
    <axis xyz="0.0 1.0 0.0"/>
  </joint>

  <joint name="dynamixel2" type="continuous">
    <origin xyz="0.0 0.037 0.08475" rpy="0 0 0"/>
    <parent link="dynamixel_block"/>
    <child link="horn_2_1"/>
    <axis xyz="0.0 1.0 0.0"/>
  </joint>

  <joint name="dynamixel3" type="continuous">
    <origin xyz="0.0 0.037 0.01425" rpy="0 0 0"/>
    <parent link="dynamixel_block"/>
    <child link="horn_3_1"/>
    <axis xyz="0.0 1.0 0.0"/>
  </joint>

  <joint name="dynamixel4" type="continuous">
    <origin xyz="-0.03 0.037 0.08475" rpy="0 0 0"/>
    <parent link="dynamixel_block"/>
    <child link="horn_4_1"/>
    <axis xyz="0.0 1.0 0.0"/>
  </joint>

  <joint name="dynamixel5" type="continuous">
    <origin xyz="-0.03 0.037 0.01425" rpy="0 0 0"/>
    <parent link="dynamixel_block"/>
    <child link="horn_5_1"/>
    <axis xyz="0.0 1.0 0.0"/>
  </joint>

  <joint name="dynamixel6" type="continuous">
    <origin xyz="-0.03 -0.037 0.08475" rpy="0 0 0"/>
    <parent link="dynamixel_block"/>
    <child link="horn_6_1"/>
    <axis xyz="0.0 -1.0 0.0"/>
  </joint>

  <joint name="dynamixel7" type="continuous">
    <origin xyz="-0.03 -0.037 0.01425" rpy="0 0 0"/>
    <parent link="dynamixel_block"/>
    <child link="horn_7_1"/>
    <axis xyz="0.0 -1.0 0.0"/>
  </joint>

  <joint name="dynamixel8" type="continuous">
    <origin xyz="0.0 -0.037 0.08475" rpy="0 0 0"/>
    <parent link="dynamixel_block"/>
    <child link="horn_8_1"/>
    <axis xyz="0.0 -1.0 0.0"/>
  </joint>

  <joint name="dynamixel9" type="continuous">
    <origin xyz="0.0 -0.037 0.01425" rpy="0 0 0"/>
    <parent link="dynamixel_block"/>
    <child link="horn_9_1"/>
    <axis xyz="0.0 -1.0 0.0"/>
  </joint>

  <joint name="dynamixel10" type="continuous">
    <origin xyz="0.03 -0.037 0.08475" rpy="0 0 0"/>
    <parent link="dynamixel_block"/>
    <child link="horn_10_1"/>
    <axis xyz="0.0 -1.0 0.0"/>
  </joint>

  <joint name="dynamixel11" type="continuous">
    <origin xyz="0.03 -0.037 0.01425" rpy="0 0 0"/>
    <parent link="dynamixel_block"/>
    <child link="horn_11_1"/>
    <axis xyz="0.0 -1.0 0.0"/>
  </joint>

</xacro:macro>
</robot>
