<?xml version="1.0" ?>
<robot name="urdf_helix" xmlns:xacro="http://www.ros.org/wiki/xacro">

<!-- URDF Representing the Helix arm -->

<xacro:arg name="mesh_url" default="package://helix_description" />

<link name="arm_base">
  <visual>
    <origin xyz="0 0 0" rpy="0 0 0"/>
      <geometry>
        <cylinder length="0.005" radius="0.03"/>
      </geometry>
    <material name="white"/>
  </visual>
</link>

<!-- Links for visualisation using floating discs, their transforms can be set manually -->

<!-- First segment -->

<joint name="seg1_mid_joint_a" type="floating">
  <parent link="arm_base"/>
  <child link="seg1_mid_link_a"/>
</joint>

<link name="seg1_mid_link_a">
  <visual>
    <origin xyz="0 0 0" rpy="0 0 0"/>
      <geometry>
        <cylinder length="0.005" radius="0.03"/>
      </geometry>
    <material name="clear"/>
  </visual>
</link>

<joint name="seg1_mid_joint_b" type="floating">
  <parent link="arm_base"/>
  <child link="seg1_mid_link_b"/>
</joint>

<link name="seg1_mid_link_b">
  <visual>
    <origin xyz="0 0 0" rpy="0 0 0"/>
      <geometry>
        <cylinder length="0.005" radius="0.03"/>
      </geometry>
    <material name="clear"/>
  </visual>
</link>

<joint name="seg1_mid_joint_c" type="floating">
  <parent link="arm_base"/>
  <child link="seg1_mid_link_c"/>
</joint>

<link name="seg1_mid_link_c">
  <visual>
    <origin xyz="0 0 0" rpy="0 0 0"/>
      <geometry>
        <cylinder length="0.005" radius="0.03"/>
      </geometry>
    <material name="clear"/>
  </visual>
</link>

<joint name="seg1_end_joint" type="floating">
  <parent link="arm_base"/>
  <child link="seg1_end_link"/>
</joint>

<link name="seg1_end_link">
  <visual>
    <origin xyz="0 0 0" rpy="0 0 0"/>
      <geometry>
        <cylinder length="0.005" radius="0.03"/>
      </geometry>
    <material name="white"/>
  </visual>
</link>

<!-- Second segment -->

<joint name="seg2_mid_joint_a" type="floating">
  <parent link="arm_base"/>
  <child link="seg2_mid_link_a"/>
</joint>

<link name="seg2_mid_link_a">
  <visual>
    <origin xyz="0 0 0" rpy="0 0 0"/>
      <geometry>
        <cylinder length="0.005" radius="0.03"/>
      </geometry>
    <material name="clear"/>
  </visual>
</link>

<joint name="seg2_mid_joint_b" type="floating">
  <parent link="arm_base"/>
  <child link="seg2_mid_link_b"/>
</joint>

<link name="seg2_mid_link_b">
  <visual>
    <origin xyz="0 0 0" rpy="0 0 0"/>
      <geometry>
        <cylinder length="0.005" radius="0.03"/>
      </geometry>
    <material name="clear"/>
  </visual>
</link>

<joint name="seg2_mid_joint_c" type="floating">
  <parent link="arm_base"/>
  <child link="seg2_mid_link_c"/>
</joint>

<link name="seg2_mid_link_c">
  <visual>
    <origin xyz="0 0 0" rpy="0 0 0"/>
      <geometry>
        <cylinder length="0.005" radius="0.03"/>
      </geometry>
    <material name="clear"/>
  </visual>
</link>

<joint name="seg2_mid_joint_d" type="floating">
  <parent link="arm_base"/>
  <child link="seg2_mid_link_d"/>
</joint>

<link name="seg2_mid_link_d">
  <visual>
    <origin xyz="0 0 0" rpy="0 0 0"/>
      <geometry>
        <cylinder length="0.005" radius="0.03"/>
      </geometry>
    <material name="clear"/>
  </visual>
</link>

<joint name="seg2_mid_joint_e" type="floating">
  <parent link="arm_base"/>
  <child link="seg2_mid_link_e"/>
</joint>

<link name="seg2_mid_link_e">
  <visual>
    <origin xyz="0 0 0" rpy="0 0 0"/>
      <geometry>
        <cylinder length="0.005" radius="0.03"/>
      </geometry>
    <material name="clear"/>
  </visual>
</link>

<joint name="seg2_mid_joint_f" type="floating">
  <parent link="arm_base"/>
  <child link="seg2_mid_link_f"/>
</joint>

<link name="seg2_mid_link_f">
  <visual>
    <origin xyz="0 0 0" rpy="0 0 0"/>
      <geometry>
        <cylinder length="0.005" radius="0.03"/>
      </geometry>
    <material name="clear"/>
  </visual>
</link>

<joint name="seg2_mid_joint_g" type="floating">
  <parent link="arm_base"/>
  <child link="seg2_mid_link_g"/>
</joint>

<link name="seg2_mid_link_g">
  <visual>
    <origin xyz="0 0 0" rpy="0 0 0"/>
      <geometry>
        <cylinder length="0.005" radius="0.03"/>
      </geometry>
    <material name="clear"/>
  </visual>
</link>

<joint name="seg2_end_joint" type="floating">
  <parent link="arm_base"/>
  <child link="seg2_end_link"/>
</joint>

<link name="seg2_end_link">
  <visual>
    <origin xyz="0 0 0" rpy="0 0 0"/>
      <geometry>
        <cylinder length="0.005" radius="0.03"/>
      </geometry>
    <material name="white"/>
  </visual>
</link>

<!-- Third segment -->

<joint name="seg3_mid_joint_a" type="floating">
  <parent link="arm_base"/>
  <child link="seg3_mid_link_a"/>
</joint>

<link name="seg3_mid_link_a">
  <visual>
    <origin xyz="0 0 0" rpy="0 0 0"/>
      <geometry>
        <cylinder length="0.005" radius="0.03"/>
      </geometry>
    <material name="clear"/>
  </visual>
</link>

<joint name="seg3_mid_joint_b" type="floating">
  <parent link="arm_base"/>
  <child link="seg3_mid_link_b"/>
</joint>

<link name="seg3_mid_link_b">
  <visual>
    <origin xyz="0 0 0" rpy="0 0 0"/>
      <geometry>
        <cylinder length="0.005" radius="0.03"/>
      </geometry>
    <material name="clear"/>
  </visual>
</link>

<joint name="seg3_mid_joint_c" type="floating">
  <parent link="arm_base"/>
  <child link="seg3_mid_link_c"/>
</joint>

<link name="seg3_mid_link_c">
  <visual>
    <origin xyz="0 0 0" rpy="0 0 0"/>
      <geometry>
        <cylinder length="0.005" radius="0.03"/>
      </geometry>
    <material name="clear"/>
  </visual>
</link>

<joint name="seg3_mid_joint_d" type="floating">
  <parent link="arm_base"/>
  <child link="seg3_mid_link_d"/>
</joint>

<link name="seg3_mid_link_d">
  <visual>
    <origin xyz="0 0 0" rpy="0 0 0"/>
      <geometry>
        <cylinder length="0.005" radius="0.03"/>
      </geometry>
    <material name="clear"/>
  </visual>
</link>

<joint name="seg3_mid_joint_e" type="floating">
  <parent link="arm_base"/>
  <child link="seg3_mid_link_e"/>
</joint>

<link name="seg3_mid_link_e">
  <visual>
    <origin xyz="0 0 0" rpy="0 0 0"/>
      <geometry>
        <cylinder length="0.005" radius="0.03"/>
      </geometry>
    <material name="clear"/>
  </visual>
</link>

<joint name="seg3_mid_joint_f" type="floating">
  <parent link="arm_base"/>
  <child link="seg3_mid_link_f"/>
</joint>

<link name="seg3_mid_link_f">
  <visual>
    <origin xyz="0 0 0" rpy="0 0 0"/>
      <geometry>
        <cylinder length="0.005" radius="0.03"/>
      </geometry>
    <material name="clear"/>
  </visual>
</link>

<joint name="seg3_mid_joint_g" type="floating">
  <parent link="arm_base"/>
  <child link="seg3_mid_link_g"/>
</joint>

<link name="seg3_mid_link_g">
  <visual>
    <origin xyz="0 0 0" rpy="0 0 0"/>
      <geometry>
        <cylinder length="0.005" radius="0.03"/>
      </geometry>
    <material name="clear"/>
  </visual>
</link>

<joint name="seg3_end_joint" type="floating">
  <parent link="arm_base"/>
  <child link="seg3_end_link"/>
</joint>

<link name="seg3_end_link">
  <visual>
    <origin xyz="0 0 0" rpy="0 0 0"/>
      <geometry>
        <cylinder length="0.005" radius="0.03"/>
      </geometry>
    <material name="white"/>
  </visual>
</link>

</robot>
