<?xml version="1.0" ?>
<robot name="urdf_helix" xmlns:xacro="http://www.ros.org/wiki/xacro">

<!-- URDF Representing the Helix arm -->

<xacro:arg name="mesh_url" default="package://helix_description" />

<xacro:include filename="$(find helix_description)/urdf/helix_arm.materials.xacro" />

<link name="arm_base">
  <visual>
    <origin xyz="0 0 0" rpy="0 0 0"/>
      <geometry>
        <cylinder length="0.005" radius="0.03"/>
      </geometry>
    <material name="white"/>
  </visual>
</link>

<link name="seg1_end_link">
  <visual>
    <origin xyz="0 0 0" rpy="0 0 0"/>
      <geometry>
        <cylinder length="0.005" radius="0.03"/>
      </geometry>
    <material name="white"/>
  </visual>
</link>

<joint name="seg1_end_joint" type="floating">
  <parent link="arm_base"/>
  <child link="seg1_end_link"/>
</joint>

<link name="seg2_end_link">
  <visual>
    <origin xyz="0 0 0" rpy="0 0 0"/>
      <geometry>
        <cylinder length="0.005" radius="0.03"/>
      </geometry>
    <material name="white"/>
  </visual>
</link>

<joint name="seg2_end_joint" type="floating">
  <parent link="arm_base"/>
  <child link="seg2_end_link"/>
</joint>

<link name="seg3_end_link">
  <visual>
    <origin xyz="0 0 0" rpy="0 0 0"/>
      <geometry>
        <cylinder length="0.005" radius="0.03"/>
      </geometry>
    <material name="white"/>
  </visual>
</link>

<joint name="seg3_end_joint" type="floating">
  <parent link="arm_base"/>
  <child link="seg3_end_link"/>
</joint>

<!-- Example below for a rigid serial chain. Maybe not relevant at all for flexible Helix arm representation. -->

<!-- <link name="Index_Base_1">
  <inertial>
    <origin xyz="-0.007201714291713072 0.005885230272430774 0.0016787722912366132" rpy="0 0 0"/>
    <mass value="0.01722650129403022"/>
    <inertia ixx="1e-06" iyy="1e-06" izz="1e-06" ixy="0.0" iyz="0.0" ixz="-0.0"/>
  </inertial>
  <visual>
    <origin xyz="0.027097 -0.003767 -0.0915" rpy="0 0 0"/>
    <geometry>
      <mesh filename="$(arg mesh_url)/meshes/Index_Base_1.stl" scale="0.001 0.001 0.001"/>
    </geometry>
    <material name="finger_base"/>
  </visual>
  <collision>
    <origin xyz="0.027097 -0.003767 -0.0915" rpy="0 0 0"/>
    <geometry>
      <mesh filename="$(arg mesh_url)/meshes/Index_Base_1.stl" scale="0.001 0.001 0.001"/>
    </geometry>
  </collision>
</link>

<link name="Index_2dof_joint_1">
  <inertial>
    <origin xyz="-0.001481711245915833 -0.0034266921818958945 0.0028828067230253634" rpy="0 0 0"/>
    <mass value="0.0074922865960129585"/>
    <inertia ixx="0.0" iyy="0.0" izz="0.0" ixy="0.0" iyz="-0.0" ixz="0.0"/>
  </inertial>
  <visual>
    <origin xyz="0.034116 -0.013147 -0.1031" rpy="0 0 0"/>
    <geometry>
      <mesh filename="$(arg mesh_url)/meshes/Index_2dof_joint_1.stl" scale="0.001 0.001 0.001"/>
    </geometry>
    <material name="2dof_joint"/>
  </visual>
  <collision>
    <origin xyz="0.034116 -0.013147 -0.1031" rpy="0 0 0"/>
    <geometry>
      <mesh filename="$(arg mesh_url)/meshes/Index_2dof_joint_1.stl" scale="0.001 0.001 0.001"/>
    </geometry>
  </collision>
</link>

<link name="Index_Proximal_1">
  <inertial>
    <origin xyz="0.0006445383282672051 0.001274183043787739 0.021749999999999825" rpy="0 0 0"/>
    <mass value="0.039861235764857395"/>
    <inertia ixx="5e-06" iyy="6e-06" izz="1e-06" ixy="0.0" iyz="-0.0" ixz="0.0"/>
  </inertial>
  <visual>
    <origin xyz="0.034299 -0.009652 -0.1121" rpy="0 0 0"/>
    <geometry>
      <mesh filename="$(arg mesh_url)/meshes/Index_Proximal_1.stl" scale="0.001 0.001 0.001"/>
    </geometry>
    <material name="proximal"/>
  </visual>
  <collision>
    <origin xyz="0.034299 -0.009652 -0.1121" rpy="0 0 0"/>
    <geometry>
      <mesh filename="$(arg mesh_url)/meshes/Index_Proximal_1.stl" scale="0.001 0.001 0.001"/>
    </geometry>
  </collision>
</link>

<link name="Index_Middle_1">
  <inertial>
    <origin xyz="-0.000786432090189769 0.0012174084476994501 0.015999999999999903" rpy="0 0 0"/>
    <mass value="0.02706545369444013"/>
    <inertia ixx="2e-06" iyy="2e-06" izz="1e-06" ixy="-0.0" iyz="0.0" ixz="0.0"/>
  </inertial>
  <visual>
    <origin xyz="0.034299 -0.009652 -0.1556" rpy="0 0 0"/>
    <geometry>
      <mesh filename="$(arg mesh_url)/meshes/Index_Middle_1.stl" scale="0.001 0.001 0.001"/>
    </geometry>
    <material name="middle"/>
  </visual>
  <collision>
    <origin xyz="0.034299 -0.009652 -0.1556" rpy="0 0 0"/>
    <geometry>
      <mesh filename="$(arg mesh_url)/meshes/Index_Middle_1.stl" scale="0.001 0.001 0.001"/>
    </geometry>
  </collision>
</link>

<link name="Index_Distal_1">
  <inertial>
    <origin xyz="0.0006324531075937584 0.0009652221564475042 0.012319161138346219" rpy="0 0 0"/>
    <mass value="0.019789884505209417"/>
    <inertia ixx="1e-06" iyy="1e-06" izz="0.0" ixy="0.0" iyz="-0.0" ixz="0.0"/>
  </inertial>
  <visual>
    <origin xyz="0.034299 -0.009652 -0.1876" rpy="0 0 0"/>
    <geometry>
      <mesh filename="$(arg mesh_url)/meshes/Index_Distal_1.stl" scale="0.001 0.001 0.001"/>
    </geometry>
    <material name="distal"/>
  </visual>
  <collision>
    <origin xyz="0.034299 -0.009652 -0.1876" rpy="0 0 0"/>
    <geometry>
      <mesh filename="$(arg mesh_url)/meshes/Index_Distal_1.stl" scale="0.001 0.001 0.001"/>
    </geometry>
  </collision>
</link>

<joint name="Index_MCP_Orth" type="continuous">
  <origin xyz="-0.007019 0.00938 0.0116" rpy="0 0 0"/>
  <parent link="Index_Base_1"/>
  <child link="Index_2dof_joint_1"/>
  <axis xyz="0.052336 0.99863 0.0"/>
</joint>

<joint name="Index_MCP" type="continuous">
  <origin xyz="-0.000183 -0.003495 0.009" rpy="0 0 0"/>
  <parent link="Index_2dof_joint_1"/>
  <child link="Index_Proximal_1"/>
  <axis xyz="-0.99863 0.052336 -0.0"/>
</joint>

<joint name="Index_PIP" type="continuous">
  <origin xyz="0.0 0.0 0.0435" rpy="0 0 0"/>
  <parent link="Index_Proximal_1"/>
  <child link="Index_Middle_1"/>
  <axis xyz="-0.99863 0.052336 0.0"/>
</joint>

<joint name="Index_DIP" type="continuous">
  <origin xyz="0.0 0.0 0.032" rpy="0 0 0"/>
  <parent link="Index_Middle_1"/>
  <child link="Index_Distal_1"/>
  <axis xyz="-0.99863 0.052336 0.0"/>
</joint> -->

</robot>
