<?xml version="1.0"?>
<robot xmlns:xacro="http://ros.org/wiki/xacro">

<!-- URDF Representing the Helix head assembly containing the motors -->

<xacro:arg name="mesh_url" default="package://helix_description" />

<xacro:macro name="motor_head" params="parent *origin">

  <joint name="origin_to_base" type="fixed">
    <xacro:insert_block name="origin" />
    <parent link="${parent}" />
    <child link="base" />
    <axis xyz="0 0 1" />
  </joint>

  <!-- Base -->
  <link name="base">
    <visual>
      <origin xyz="0 0 0" rpy="0 0 0"/>
      <geometry>
        <cylinder length="0.01" radius="0.15"/>
      </geometry>
      <material name='clear'/>
    </visual>
    <visual>
      <origin xyz="0 0 0.07" rpy="0 0 0"/>
      <geometry>
        <cylinder length="0.01" radius="0.15"/>
      </geometry>
      <material name='clear'/>
    </visual>
     <visual>
      <origin xyz="0 0 0.14" rpy="0 0 0"/>
      <geometry>
        <cylinder length="0.01" radius="0.15"/>
      </geometry>
      <material name='clear'/>
    </visual>
  </link>

  <!-- Joint 0 -->
  <joint name="joint0" type="continuous">
    <parent link="base"/>
    <child link="link0"/>
    <origin xyz="-0.043 0.025 0.12" rpy="0 0 4.2"/>
    <axis xyz="1 0 0"/>
  </joint>

   <!-- Link 0 -->
  <link name="link0">
    <visual>
      <origin xyz="0 0 0" rpy="0 1.57 0"/>
      <geometry>
        <cylinder length="0.015" radius="0.02"/>
      </geometry>
      <material name="black"/>
    </visual>
  </link>

  <!-- Joint 1 -->
  <joint name="joint1" type="continuous">
    <parent link="base"/>
    <child link="link1"/>
    <origin xyz="0 -0.05 0.12" rpy="0 0 0"/>
    <axis xyz="1 0 0"/>
  </joint>

   <!-- Link 1 -->
  <link name="link1">
    <visual>
      <origin xyz="0 0 0" rpy="0 1.57 0"/>
      <geometry>
        <cylinder length="0.015" radius="0.02"/>
      </geometry>
      <material name="black"/>
    </visual>
  </link>

  <!-- Joint 2 -->
  <joint name="joint2" type="continuous">
    <parent link="base"/>
    <child link="link2"/>
    <origin xyz="0.043 0.025 0.12" rpy="0 0 2.1"/>
    <axis xyz="1 0 0"/>
    continuous
  </joint>

   <!-- Link 2 -->
  <link name="link2">
    <visual>
      <origin xyz="0 0 0" rpy="0 1.57 0"/>
      <geometry>
        <cylinder length="0.015" radius="0.02"/>
      </geometry>
      <material name="black"/>
    </visual>
  </link>

  <!-- Joint 3 -->
  <joint name="joint3" type="continuous">
    <parent link="base"/>
    <child link="link3"/>
    <origin xyz="0.16 0 0.025" rpy="0 0 0"/>
    <axis xyz="1 0 0"/>
  </joint>

   <!-- Link 3 -->
  <link name="link3">
    <visual>
      <origin xyz="0 0 0" rpy="0 1.57 0"/>
      <geometry>
        <cylinder length="0.015" radius="0.02"/>
      </geometry>
      <material name="black"/>
    </visual>
  </link>

  <!-- Joint 4 -->
  <joint name="joint4" type="continuous">
    <parent link="base"/>
    <child link="link4"/>
    <origin xyz="-0.08 0.138 0.025" rpy="0 0 2.1"/>
    <axis xyz="1 0 0"/>
  </joint>

   <!-- Link 4 -->
  <link name="link4">
    <visual>
      <origin xyz="0 0 0" rpy="0 1.57 0"/>
      <geometry>
        <cylinder length="0.015" radius="0.02"/>
      </geometry>
      <material name="black"/>
    </visual>
  </link>

  <!-- Joint 5 -->
  <joint name="joint5" type="continuous">
    <parent link="base"/>
    <child link="link5"/>
    <origin xyz="-0.08 -0.138 0.025" rpy="0 0 4.2"/>
    <axis xyz="1 0 0"/>
  </joint>

   <!-- Link 5 -->
  <link name="link5">
    <visual>
      <origin xyz="0 0 0" rpy="0 1.57 0"/>
      <geometry>
        <cylinder length="0.015" radius="0.02"/>
      </geometry>
      <material name="black"/>
    </visual>
  </link>

  <!-- Joint 6 -->
  <joint name="joint6" type="continuous">
    <parent link="base"/>
    <child link="link6"/>
    <origin xyz="0.08 -0.138 0.025" rpy="0 0 5.2"/>
    <axis xyz="1 0 0"/>
  </joint>

   <!-- Link 6 -->
  <link name="link6">
    <visual>
      <origin xyz="0 0 0" rpy="0 1.57 0"/>
      <geometry>
        <cylinder length="0.015" radius="0.02"/>
      </geometry>
      <material name="black"/>
    </visual>
  </link>

  <!-- Joint 7 -->
  <joint name="joint7" type="continuous">
    <parent link="base"/>
    <child link="link7"/>
    <origin xyz="0.08 0.138 0.025" rpy="0 0 1.0"/>
    <axis xyz="1 0 0"/>
  </joint>

   <!-- Link 7 -->
  <link name="link7">
    <visual>
      <origin xyz="0 0 0" rpy="0 1.57 0"/>
      <geometry>
        <cylinder length="0.015" radius="0.02"/>
      </geometry>
      <material name="black"/>
    </visual>
  </link>

  <!-- Joint 8 -->
  <joint name="joint8" type="continuous">
    <parent link="base"/>
    <child link="link8"/>
    <origin xyz="-0.16 0 0.025" rpy="0 0 3.1"/>
    <axis xyz="1 0 0"/>
  </joint>

   <!-- Link 8 -->
  <link name="link8">
    <visual>
      <origin xyz="0 0 0" rpy="0 1.57 0"/>
      <geometry>
        <cylinder length="0.015" radius="0.02"/>
      </geometry>
      <material name="black"/>
    </visual>
  </link>

  <!-- Gripper Joint -->
  <joint name="joint_gripper" type="continuous">
    <parent link="base"/>
    <child link="link_gripper"/>
    <origin xyz="0 0 0.2" rpy="0 0 0"/>
    <axis xyz="1 0 0"/>
  </joint>

   <!-- Gripper Link -->
  <link name="link_gripper">
    <visual>
      <origin xyz="0 0 0" rpy="0 1.57 0"/>
      <geometry>
        <cylinder length="0.015" radius="0.02"/>
      </geometry>
      <material name="black"/>
    </visual>
  </link>

</xacro:macro>

</robot>